[2022-05-30 18:13:26,649] {taskinstance.py:1035} INFO - Dependencies all met for <TaskInstance: download_rocket_launches.download_launches manual__2022-05-30T18:13:24.711962+00:00 [queued]>
[2022-05-30 18:13:26,668] {taskinstance.py:1035} INFO - Dependencies all met for <TaskInstance: download_rocket_launches.download_launches manual__2022-05-30T18:13:24.711962+00:00 [queued]>
[2022-05-30 18:13:26,669] {taskinstance.py:1241} INFO - 
--------------------------------------------------------------------------------
[2022-05-30 18:13:26,669] {taskinstance.py:1242} INFO - Starting attempt 1 of 1
[2022-05-30 18:13:26,669] {taskinstance.py:1243} INFO - 
--------------------------------------------------------------------------------
[2022-05-30 18:13:26,681] {taskinstance.py:1262} INFO - Executing <Task(BashOperator): download_launches> on 2022-05-30 18:13:24.711962+00:00
[2022-05-30 18:13:26,687] {standard_task_runner.py:52} INFO - Started process 8642 to run task
[2022-05-30 18:13:26,692] {standard_task_runner.py:76} INFO - Running: ['***', 'tasks', 'run', 'download_rocket_launches', 'download_launches', 'manual__2022-05-30T18:13:24.711962+00:00', '--job-id', '3', '--raw', '--subdir', 'DAGS_FOLDER/rocket_launches.py', '--cfg-path', '/tmp/tmpfa7djlbl', '--error-file', '/tmp/tmp7ukhxmb3']
[2022-05-30 18:13:26,693] {standard_task_runner.py:77} INFO - Job 3: Subtask download_launches
[2022-05-30 18:13:26,737] {logging_mixin.py:109} INFO - Running <TaskInstance: download_rocket_launches.download_launches manual__2022-05-30T18:13:24.711962+00:00 [running]> on host b6b47ea722e0
[2022-05-30 18:13:26,781] {taskinstance.py:1414} INFO - Exporting the following env vars:
AIRFLOW_CTX_DAG_OWNER=***
AIRFLOW_CTX_DAG_ID=download_rocket_launches
AIRFLOW_CTX_TASK_ID=download_launches
AIRFLOW_CTX_EXECUTION_DATE=2022-05-30T18:13:24.711962+00:00
AIRFLOW_CTX_DAG_RUN_ID=manual__2022-05-30T18:13:24.711962+00:00
[2022-05-30 18:13:26,784] {subprocess.py:62} INFO - Tmp dir root location: 
 /tmp
[2022-05-30 18:13:26,785] {subprocess.py:74} INFO - Running command: ['bash', '-c', "curl -o /tmp/launches.json -L 'https://ll.thespacedevs.com/2.0.0/launch/upcoming'"]
[2022-05-30 18:13:26,797] {subprocess.py:85} INFO - Output:
[2022-05-30 18:13:26,807] {subprocess.py:89} INFO -   % Total    % Received % Xferd  Average Speed   Time    Time     Time  Current
[2022-05-30 18:13:26,808] {subprocess.py:89} INFO -                                  Dload  Upload   Total   Spent    Left  Speed
[2022-05-30 18:13:36,891] {subprocess.py:89} INFO -   0     0    0     0    0     0      0      0 --:--:-- --:--:-- --:--:--     0  0     0    0     0    0     0      0      0 --:--:--  0:00:01 --:--:--     0  0     0    0     0    0     0      0      0 --:--:--  0:00:02 --:--:--     0  0     0    0     0    0     0      0      0 --:--:--  0:00:03 --:--:--     0  0     0    0     0    0     0      0      0 --:--:--  0:00:04 --:--:--     0  0     0    0     0    0     0      0      0 --:--:--  0:00:05 --:--:--     0  0     0    0     0    0     0      0      0 --:--:--  0:00:06 --:--:--     0  0     0    0     0    0     0      0      0 --:--:--  0:00:07 --:--:--     0  0     0    0     0    0     0      0      0 --:--:--  0:00:08 --:--:--     0  0     0    0     0    0     0      0      0 --:--:--  0:00:09 --:--:--     0curl: (6) Could not resolve host: ll.thespacedevs.com
[2022-05-30 18:13:36,891] {subprocess.py:93} INFO - Command exited with return code 6
[2022-05-30 18:13:36,894] {taskinstance.py:1686} ERROR - Task failed with exception
Traceback (most recent call last):
  File "/home/airflow/.local/lib/python3.6/site-packages/airflow/models/taskinstance.py", line 1324, in _run_raw_task
    self._execute_task_with_callbacks(context)
  File "/home/airflow/.local/lib/python3.6/site-packages/airflow/models/taskinstance.py", line 1443, in _execute_task_with_callbacks
    result = self._execute_task(context, self.task)
  File "/home/airflow/.local/lib/python3.6/site-packages/airflow/models/taskinstance.py", line 1499, in _execute_task
    result = execute_callable(context=context)
  File "/home/airflow/.local/lib/python3.6/site-packages/airflow/operators/bash.py", line 188, in execute
    f'Bash command failed. The command returned a non-zero exit code {result.exit_code}.'
airflow.exceptions.AirflowException: Bash command failed. The command returned a non-zero exit code 6.
[2022-05-30 18:13:36,909] {taskinstance.py:1280} INFO - Marking task as FAILED. dag_id=download_rocket_launches, task_id=download_launches, execution_date=20220530T181324, start_date=20220530T181326, end_date=20220530T181336
[2022-05-30 18:13:36,932] {standard_task_runner.py:91} ERROR - Failed to execute job 3 for task download_launches
Traceback (most recent call last):
  File "/home/airflow/.local/lib/python3.6/site-packages/airflow/task/task_runner/standard_task_runner.py", line 85, in _start_by_fork
    args.func(args, dag=self.dag)
  File "/home/airflow/.local/lib/python3.6/site-packages/airflow/cli/cli_parser.py", line 48, in command
    return func(*args, **kwargs)
  File "/home/airflow/.local/lib/python3.6/site-packages/airflow/utils/cli.py", line 92, in wrapper
    return f(*args, **kwargs)
  File "/home/airflow/.local/lib/python3.6/site-packages/airflow/cli/commands/task_command.py", line 292, in task_run
    _run_task_by_selected_method(args, dag, ti)
  File "/home/airflow/.local/lib/python3.6/site-packages/airflow/cli/commands/task_command.py", line 107, in _run_task_by_selected_method
    _run_raw_task(args, ti)
  File "/home/airflow/.local/lib/python3.6/site-packages/airflow/cli/commands/task_command.py", line 184, in _run_raw_task
    error_file=args.error_file,
  File "/home/airflow/.local/lib/python3.6/site-packages/airflow/utils/session.py", line 70, in wrapper
    return func(*args, session=session, **kwargs)
  File "/home/airflow/.local/lib/python3.6/site-packages/airflow/models/taskinstance.py", line 1324, in _run_raw_task
    self._execute_task_with_callbacks(context)
  File "/home/airflow/.local/lib/python3.6/site-packages/airflow/models/taskinstance.py", line 1443, in _execute_task_with_callbacks
    result = self._execute_task(context, self.task)
  File "/home/airflow/.local/lib/python3.6/site-packages/airflow/models/taskinstance.py", line 1499, in _execute_task
    result = execute_callable(context=context)
  File "/home/airflow/.local/lib/python3.6/site-packages/airflow/operators/bash.py", line 188, in execute
    f'Bash command failed. The command returned a non-zero exit code {result.exit_code}.'
airflow.exceptions.AirflowException: Bash command failed. The command returned a non-zero exit code 6.
[2022-05-30 18:13:36,963] {local_task_job.py:154} INFO - Task exited with return code 1
[2022-05-30 18:13:37,001] {local_task_job.py:264} INFO - 0 downstream tasks scheduled from follow-on schedule check
